Workbook
Name Names: 'All data'!$B$2:$B$479
Name Cond: 'All data'!$P$2:$P$479
Name CorrectN: 'All data'!$Q$2:$Q$479
Name RtN: 'All data'!$R$2:$R$479
Name AbsN: 'All data'!$S$2:$S$479
Name Scored: 'All data'!$T$2:$T$479

Sheet All data
A1: participant | B1: name | C1: condition | D1: date | E1: trial | F1: numbers | G1: sum | H1: answer | I1: correct | J1: diff | K1: rt_ms | L1: count | M1: show_s | N1: min | O1: max | P1: condition used | Q1: correct (1/0) | R1: rt used (ms) | S1: absolute error used | T1: in test
A2: 1 | B2: Cas | C2: lyrics | D2: 2026-10-11T17:50:02.721Z | E2: 1 | F2: 1 2 3 4 9 4 7 1 | G2: 31 | H2: 29 | I2: false | J2: 2 | K2: 2507 | L2: 8 | M2: 1.8 | N2: 1 | O2: 9 | P2: =LOWER(TRIM(C2)) | Q2: =IF(I2="true",1,0) | R2: =IF(K2="","",K2) | S2: =IF(OR(H2="",H2<8,H2>72),"",J2) | T2: =IF(OR(P2="lyrics",P2="instrumental"),1,IF(AND(P2="none",COUNTIFS($B$2:$B$479,B2,$P$2:$P$479,"none")>=3),1,0))
A3: 1 | B3: Cas | C3: lyrics | D3: 2026-10-11T17:50:02.721Z | E3: 2 | F3: 2 8 4 1 5 9 7 8 | G3: 44 | H3: 44 | I3: true | J3: 0 | K3: 2542 | L3: 8 | M3: 1.8 | N3: 1 | O3: 9 | P3: =LOWER(TRIM(C3)) | Q3: =IF(I3="true",1,0) | R3: =IF(K3="","",K3) | S3: =IF(OR(H3="",H3<8,H3>72),"",J3) | T3: =IF(OR(P3="lyrics",P3="instrumental"),1,IF(AND(P3="none",COUNTIFS($B$2:$B$479,B3,$P$2:$P$479,"none")>=3),1,0))
A4: 1 | B4: Cas | C4: lyrics | D4: 2026-10-11T17:50:02.721Z | E4: 3 | F4: 7 2 5 2 2 7 7 2 | G4: 34 | H4: 34 | I4: true | J4: 0 | K4: 1967 | L4: 8 | M4: 1.8 | N4: 1 | O4: 9 | P4: =LOWER(TRIM(C4)) | Q4: =IF(I4="true",1,0) | R4: =IF(K4="","",K4) | S4: =IF(OR(H4="",H4<8,H4>72),"",J4) | T4: =IF(OR(P4="lyrics",P4="instrumental"),1,IF(AND(P4="none",COUNTIFS($B$2:$B$479,B4,$P$2:$P$479,"none")>=3),1,0))
A5: 2 | B5: Cas | C5: none | D5: 2026-10-11T17:53:20.646Z | E5: 1 | F5: 9 4 3 2 9 1 8 4 | G5: 40 | H5: 40 | I5: true | J5: 0 | K5: 1694 | L5: 8 | M5: 1.8 | N5: 1 | O5: 9 | P5: =LOWER(TRIM(C5)) | Q5: =IF(I5="true",1,0) | R5: =IF(K5="","",K5) | S5: =IF(OR(H5="",H5<8,H5>72),"",J5) | T5: =IF(OR(P5="lyrics",P5="instrumental"),1,IF(AND(P5="none",COUNTIFS($B$2:$B$479,B5,$P$2:$P$479,"none")>=3),1,0))
A6: 2 | B6: Cas | C6: none | D6: 2026-10-11T17:53:20.646Z | E6: 2 | F6: 8 8 5 9 6 7 3 3 | G6: 49 | H6: 49 | I6: true | J6: 0 | K6: 1648 | L6: 8 | M6: 1.8 | N6: 1 | O6: 9 | P6: =LOWER(TRIM(C6)) | Q6: =IF(I6="true",1,0) | R6: =IF(K6="","",K6) | S6: =IF(OR(H6="",H6<8,H6>72),"",J6) | T6: =IF(OR(P6="lyrics",P6="instrumental"),1,IF(AND(P6="none",COUNTIFS($B$2:$B$479,B6,$P$2:$P$479,"none")>=3),1,0))
A7: 2 | B7: Cas | C7: none | D7: 2026-10-11T17:53:20.646Z | E7: 3 | F7: 6 8 9 4 5 3 6 9 | G7: 50 | H7: 50 | I7: true | J7: 0 | K7: 1535 | L7: 8 | M7: 1.8 | N7: 1 | O7: 9 | P7: =LOWER(TRIM(C7)) | Q7: =IF(I7="true",1,0) | R7: =IF(K7="","",K7) | S7: =IF(OR(H7="",H7<8,H7>72),"",J7) | T7: =IF(OR(P7="lyrics",P7="instrumental"),1,IF(AND(P7="none",COUNTIFS($B$2:$B$479,B7,$P$2:$P$479,"none")>=3),1,0))
A8: 3 | B8: Cas | C8: instrumental | D8: 2026-10-11T17:54:49.473Z | E8: 1 | F8: 9 9 4 6 4 1 5 6 | G8: 44 | H8: 43 | I8: false | J8: 1 | K8: 1820 | L8: 8 | M8: 1.8 | N8: 1 | O8: 9 | P8: =LOWER(TRIM(C8)) | Q8: =IF(I8="true",1,0) | R8: =IF(K8="","",K8) | S8: =IF(OR(H8="",H8<8,H8>72),"",J8) | T8: =IF(OR(P8="lyrics",P8="instrumental"),1,IF(AND(P8="none",COUNTIFS($B$2:$B$479,B8,$P$2:$P$479,"none")>=3),1,0))
A9: 3 | B9: Cas | C9: instrumental | D9: 2026-10-11T17:54:49.473Z | E9: 2 | F9: 7 3 7 2 3 1 4 3 | G9: 30 | H9: 30 | I9: true | J9: 0 | K9: 2036 | L9: 8 | M9: 1.8 | N9: 1 | O9: 9 | P9: =LOWER(TRIM(C9)) | Q9: =IF(I9="true",1,0) | R9: =IF(K9="","",K9) | S9: =IF(OR(H9="",H9<8,H9>72),"",J9) | T9: =IF(OR(P9="lyrics",P9="instrumental"),1,IF(AND(P9="none",COUNTIFS($B$2:$B$479,B9,$P$2:$P$479,"none")>=3),1,0))
A10: 3 | B10: Cas | C10: instrumental | D10: 2026-10-11T17:54:49.473Z | E10: 3 | F10: 1 7 6 3 7 4 3 7 | G10: 38 | H10: 38 | I10: true | J10: 0 | K10: 1616 | L10: 8 | M10: 1.8 | N10: 1 | O10: 9 | P10: =LOWER(TRIM(C10)) | Q10: =IF(I10="true",1,0) | R10: =IF(K10="","",K10) | S10: =IF(OR(H10="",H10<8,H10>72),"",J10) | T10: =IF(OR(P10="lyrics",P10="instrumental"),1,IF(AND(P10="none",COUNTIFS($B$2:$B$479,B10,$P$2:$P$479,"none")>=3),1,0))
A11: 4 | B11: Floor | C11: instrumental | D11: 2026-10-11T17:56:07.560Z | E11: 1 | F11: 2 9 9 6 3 9 8 3 | G11: 49 | H11: 49 | I11: true | J11: 0 | K11: 3528 | L11: 8 | M11: 1.8 | N11: 1 | O11: 9 | P11: =LOWER(TRIM(C11)) | Q11: =IF(I11="true",1,0) | R11: =IF(K11="","",K11) | S11: =IF(OR(H11="",H11<8,H11>72),"",J11) | T11: =IF(OR(P11="lyrics",P11="instrumental"),1,IF(AND(P11="none",COUNTIFS($B$2:$B$479,B11,$P$2:$P$479,"none")>=3),1,0))
A12: 4 | B12: Floor | C12: instrumental | D12: 2026-10-11T17:56:07.560Z | E12: 2 | F12: 2 4 1 3 6 7 2 5 | G12: 30 | H12: 30 | I12: true | J12: 0 | K12: 3439 | L12: 8 | M12: 1.8 | N12: 1 | O12: 9 | P12: =LOWER(TRIM(C12)) | Q12: =IF(I12="true",1,0) | R12: =IF(K12="","",K12) | S12: =IF(OR(H12="",H12<8,H12>72),"",J12) | T12: =IF(OR(P12="lyrics",P12="instrumental"),1,IF(AND(P12="none",COUNTIFS($B$2:$B$479,B12,$P$2:$P$479,"none")>=3),1,0))
A13: 4 | B13: Floor | C13: instrumental | D13: 2026-10-11T17:56:07.560Z | E13: 3 | F13: 8 4 1 1 3 3 6 7 | G13: 33 | H13: 33 | I13: true | J13: 0 | K13: 3371 | L13: 8 | M13: 1.8 | N13: 1 | O13: 9 | P13: =LOWER(TRIM(C13)) | Q13: =IF(I13="true",1,0) | R13: =IF(K13="","",K13) | S13: =IF(OR(H13="",H13<8,H13>72),"",J13) | T13: =IF(OR(P13="lyrics",P13="instrumental"),1,IF(AND(P13="none",COUNTIFS($B$2:$B$479,B13,$P$2:$P$479,"none")>=3),1,0))
... A93: 31 | B93: Participant 1 | C93: instrumental | D93: 2026-10-10T11:06:39.239Z | E93: 3 | F93: 4 4 4 6 2 5 2 8 | G93: 35 | H93: 35 | I93: true | J93: 0 | K93: 3286 | L93: 8 | M93: 1.8 | N93: 1 | O93: 9 | P93: =LOWER(TRIM(C93)) | Q93: =IF(I93="true",1,0) | R93: =IF(K93="","",K93) | S93: =IF(OR(H93="",H93<8,H93>72),"",J93) | T93: =IF(OR(P93="lyrics",P93="instrumental"),1,IF(AND(P93="none",COUNTIFS($B$2:$B$479,B93,$P$2:$P$479,"none")>=3),1,0))
A94: 32 | B94: Participant 2 | C94: none | D94: 2026-10-10T19:29:54.418Z | E94: 1 | F94: 7 6 1 3 8 4 4 8 | G94: 41 | H94: 38 | I94: false | J94: 3 | L94: 8 | M94: 1.8 | N94: 1 | O94: 9 | P94: =LOWER(TRIM(C94)) | Q94: =IF(I94="true",1,0) | R94: =IF(K94="","",K94) | S94: =IF(OR(H94="",H94<8,H94>72),"",J94) | T94: =IF(OR(P94="lyrics",P94="instrumental"),1,IF(AND(P94="none",COUNTIFS($B$2:$B$479,B94,$P$2:$P$479,"none")>=3),1,0))
A95: 32 | B95: Participant 2 | C95: none | D95: 2026-10-10T19:29:54.418Z | E95: 2 | F95: 8 4 4 7 6 7 5 2 | G95: 43 | H95: 44 | I95: false | J95: 1 | K95: 6825 | L95: 8 | M95: 1.8 | N95: 1 | O95: 9 | P95: =LOWER(TRIM(C95)) | Q95: =IF(I95="true",1,0) | R95: =IF(K95="","",K95) | S95: =IF(OR(H95="",H95<8,H95>72),"",J95) | T95: =IF(OR(P95="lyrics",P95="instrumental"),1,IF(AND(P95="none",COUNTIFS($B$2:$B$479,B95,$P$2:$P$479,"none")>=3),1,0))
A96: 33 | B96: Participant 2 | C96: instrumental | D96: 2026-10-10T19:32:34.950Z | E96: 1 | F96: 7 1 6 3 7 6 5 4 | G96: 39 | H96: 49 | I96: false | J96: 10 | K96: 7814 | L96: 8 | M96: 1.8 | N96: 1 | O96: 9 | P96: =LOWER(TRIM(C96)) | Q96: =IF(I96="true",1,0) | R96: =IF(K96="","",K96) | S96: =IF(OR(H96="",H96<8,H96>72),"",J96) | T96: =IF(OR(P96="lyrics",P96="instrumental"),1,IF(AND(P96="none",COUNTIFS($B$2:$B$479,B96,$P$2:$P$479,"none")>=3),1,0))
A97: 33 | B97: Participant 2 | C97: instrumental | D97: 2026-10-10T19:32:34.950Z | E97: 2 | F97: 8 1 4 8 5 8 1 1 | G97: 36 | H97: 38 | I97: false | J97: 2 | K97: 2867 | L97: 8 | M97: 1.8 | N97: 1 | O97: 9 | P97: =LOWER(TRIM(C97)) | Q97: =IF(I97="true",1,0) | R97: =IF(K97="","",K97) | S97: =IF(OR(H97="",H97<8,H97>72),"",J97) | T97: =IF(OR(P97="lyrics",P97="instrumental"),1,IF(AND(P97="none",COUNTIFS($B$2:$B$479,B97,$P$2:$P$479,"none")>=3),1,0))
A98: 33 | B98: Participant 2 | C98: instrumental | D98: 2026-10-10T19:32:34.950Z | E98: 3 | F98: 7 8 3 1 4 9 8 6 | G98: 46 | H98: 46 | I98: true | J98: 0 | K98: 2119 | L98: 8 | M98: 1.8 | N98: 1 | O98: 9 | P98: =LOWER(TRIM(C98)) | Q98: =IF(I98="true",1,0) | R98: =IF(K98="","",K98) | S98: =IF(OR(H98="",H98<8,H98>72),"",J98) | T98: =IF(OR(P98="lyrics",P98="instrumental"),1,IF(AND(P98="none",COUNTIFS($B$2:$B$479,B98,$P$2:$P$479,"none")>=3),1,0))
A99: 34 | B99: Participant 2 | C99: lyrics | D99: 2026-10-10T19:34:13.947Z | E99: 1 | F99: 2 8 9 3 5 3 9 5 | G99: 44 | H99: 44 | I99: true | J99: 0 | K99: 2097 | L99: 8 | M99: 1.8 | N99: 1 | O99: 9 | P99: =LOWER(TRIM(C99)) | Q99: =IF(I99="true",1,0) | R99: =IF(K99="","",K99) | S99: =IF(OR(H99="",H99<8,H99>72),"",J99) | T99: =IF(OR(P99="lyrics",P99="instrumental"),1,IF(AND(P99="none",COUNTIFS($B$2:$B$479,B99,$P$2:$P$479,"none")>=3),1,0))
A100: 34 | B100: Participant 2 | C100: lyrics | D100: 2026-10-10T19:34:13.947Z | E100: 2 | F100: 3 6 5 3 8 9 6 8 | G100: 48 | H100: 48 | I100: true | J100: 0 | K100: 2201 | L100: 8 | M100: 1.8 | N100: 1 | O100: 9 | P100: =LOWER(TRIM(C100)) | Q100: =IF(I100="true",1,0) | R100: =IF(K100="","",K100) | S100: =IF(OR(H100="",H100<8,H100>72),"",J100) | T100: =IF(OR(P100="lyrics",P100="instrumental"),1,IF(AND(P100="none",COUNTIFS($B$2:$B$479,B100,$P$2:$P$479,"none")>=3),1,0))
A101: 34 | B101: Participant 2 | C101: lyrics | D101: 2026-10-10T19:34:13.947Z | E101: 3 | F101: 8 3 8 3 5 1 4 8 | G101: 40 | H101: 40 | I101: true | J101: 0 | K101: 1887 | L101: 8 | M101: 1.8 | N101: 1 | O101: 9 | P101: =LOWER(TRIM(C101)) | Q101: =IF(I101="true",1,0) | R101: =IF(K101="","",K101) | S101: =IF(OR(H101="",H101<8,H101>72),"",J101) | T101: =IF(OR(P101="lyrics",P101="instrumental"),1,IF(AND(P101="none",COUNTIFS($B$2:$B$479,B101,$P$2:$P$479,"none")>=3),1,0))
A102: 35 | B102: Participant 2 | C102: instrumental | D102: 2026-10-10T19:36:02.411Z | E102: 1 | F102: 7 8 4 6 9 4 1 6 | G102: 45 | H102: 45 | I102: true | J102: 0 | K102: 4384 | L102: 8 | M102: 1.8 | N102: 1 | O102: 9 | P102: =LOWER(TRIM(C102)) | Q102: =IF(I102="true",1,0) | R102: =IF(K102="","",K102) | S102: =IF(OR(H102="",H102<8,H102>72),"",J102) | T102: =IF(OR(P102="lyrics",P102="instrumental"),1,IF(AND(P102="none",COUNTIFS($B$2:$B$479,B102,$P$2:$P$479,"none")>=3),1,0))
A103: 35 | B103: Participant 2 | C103: instrumental | D103: 2026-10-10T19:36:02.411Z | E103: 2 | F103: 9 6 4 4 1 6 5 6 | G103: 41 | H103: 41 | I103: true | J103: 0 | K103: 1797 | L103: 8 | M103: 1.8 | N103: 1 | O103: 9 | P103: =LOWER(TRIM(C103)) | Q103: =IF(I103="true",1,0) | R103: =IF(K103="","",K103) | S103: =IF(OR(H103="",H103<8,H103>72),"",J103) | T103: =IF(OR(P103="lyrics",P103="instrumental"),1,IF(AND(P103="none",COUNTIFS($B$2:$B$479,B103,$P$2:$P$479,"none")>=3),1,0))
A104: 35 | B104: Participant 2 | C104: instrumental | D104: 2026-10-10T19:36:02.411Z | E104: 3 | F104: 9 9 7 4 5 3 8 7 | G104: 52 | H104: 43 | I104: false | J104: 9 | K104: 3471 | L104: 8 | M104: 1.8 | N104: 1 | O104: 9 | P104: =LOWER(TRIM(C104)) | Q104: =IF(I104="true",1,0) | R104: =IF(K104="","",K104) | S104: =IF(OR(H104="",H104<8,H104>72),"",J104) | T104: =IF(OR(P104="lyrics",P104="instrumental"),1,IF(AND(P104="none",COUNTIFS($B$2:$B$479,B104,$P$2:$P$479,"none")>=3),1,0))
A105: 36 | B105: Participant 2 | C105: lyrics | D105: 2026-10-10T19:38:14.208Z | E105: 1 | F105: 1 8 3 7 8 5 7 4 | G105: 43 | H105: 43 | I105: true | J105: 0 | K105: 5919 | L105: 8 | M105: 1.8 | N105: 1 | O105: 9 | P105: =LOWER(TRIM(C105)) | Q105: =IF(I105="true",1,0) | R105: =IF(K105="","",K105) | S105: =IF(OR(H105="",H105<8,H105>72),"",J105) | T105: =IF(OR(P105="lyrics",P105="instrumental"),1,IF(AND(P105="none",COUNTIFS($B$2:$B$479,B105,$P$2:$P$479,"none")>=3),1,0))
A106: 36 | B106: Participant 2 | C106: lyrics | D106: 2026-10-10T19:38:14.208Z | E106: 2 | F106: 1 9 9 7 5 7 3 8 | G106: 49 | H106: 49 | I106: true | J106: 0 | K106: 2150 | L106: 8 | M106: 1.8 | N106: 1 | O106: 9 | P106: =LOWER(TRIM(C106)) | Q106: =IF(I106="true",1,0) | R106: =IF(K106="","",K106) | S106: =IF(OR(H106="",H106<8,H106>72),"",J106) | T106: =IF(OR(P106="lyrics",P106="instrumental"),1,IF(AND(P106="none",COUNTIFS($B$2:$B$479,B106,$P$2:$P$479,"none")>=3),1,0))
... A142: 49 | B142: Participant 4 | C142: lyrics | D142: 2026-10-11T17:07:59.681Z | E142: 1 | F142: 6 4 7 2 8 8 9 5 | G142: 49 | H142: 49 | I142: true | J142: 0 | K142: 2681 | L142: 8 | M142: 1.8 | N142: 1 | O142: 9 | P142: =LOWER(TRIM(C142)) | Q142: =IF(I142="true",1,0) | R142: =IF(K142="","",K142) | S142: =IF(OR(H142="",H142<8,H142>72),"",J142) | T142: =IF(OR(P142="lyrics",P142="instrumental"),1,IF(AND(P142="none",COUNTIFS($B$2:$B$479,B142,$P$2:$P$479,"none")>=3),1,0))
A143: 49 | B143: Participant 4 | C143: lyrics | D143: 2026-10-11T17:07:59.681Z | E143: 2 | F143: 4 5 8 8 9 2 9 4 | G143: 49 | I143: false | L143: 8 | M143: 1.8 | N143: 1 | O143: 9 | P143: =LOWER(TRIM(C143)) | Q143: =IF(I143="true",1,0) | R143: =IF(K143="","",K143) | S143: =IF(OR(H143="",H143<8,H143>72),"",J143) | T143: =IF(OR(P143="lyrics",P143="instrumental"),1,IF(AND(P143="none",COUNTIFS($B$2:$B$479,B143,$P$2:$P$479,"none")>=3),1,0))
A144: 49 | B144: Participant 4 | C144: lyrics | D144: 2026-10-11T17:07:59.681Z | E144: 3 | F144: 3 1 9 8 8 6 5 4 | G144: 44 | H144: 46 | I144: false | J144: 2 | K144: 4975 | L144: 8 | M144: 1.8 | N144: 1 | O144: 9 | P144: =LOWER(TRIM(C144)) | Q144: =IF(I144="true",1,0) | R144: =IF(K144="","",K144) | S144: =IF(OR(H144="",H144<8,H144>72),"",J144) | T144: =IF(OR(P144="lyrics",P144="instrumental"),1,IF(AND(P144="none",COUNTIFS($B$2:$B$479,B144,$P$2:$P$479,"none")>=3),1,0))
A145: 50 | B145: Participant 4 | C145: lyrics | D145: 2026-10-11T17:09:33.616Z | E145: 1 | F145: 3 1 2 4 5 9 6 1 | G145: 31 | H145: 31 | I145: true | J145: 0 | K145: 1320 | L145: 8 | M145: 1.8 | N145: 1 | O145: 9 | P145: =LOWER(TRIM(C145)) | Q145: =IF(I145="true",1,0) | R145: =IF(K145="","",K145) | S145: =IF(OR(H145="",H145<8,H145>72),"",J145) | T145: =IF(OR(P145="lyrics",P145="instrumental"),1,IF(AND(P145="none",COUNTIFS($B$2:$B$479,B145,$P$2:$P$479,"none")>=3),1,0))
A146: 50 | B146: Participant 4 | C146: lyrics | D146: 2026-10-11T17:09:33.616Z | E146: 2 | F146: 9 3 4 5 8 1 3 9 | G146: 42 | H146: 42 | I146: true | J146: 0 | K146: 3824 | L146: 8 | M146: 1.8 | N146: 1 | O146: 9 | P146: =LOWER(TRIM(C146)) | Q146: =IF(I146="true",1,0) | R146: =IF(K146="","",K146) | S146: =IF(OR(H146="",H146<8,H146>72),"",J146) | T146: =IF(OR(P146="lyrics",P146="instrumental"),1,IF(AND(P146="none",COUNTIFS($B$2:$B$479,B146,$P$2:$P$479,"none")>=3),1,0))
A147: 50 | B147: Participant 4 | C147: lyrics | D147: 2026-10-11T17:09:33.616Z | E147: 3 | F147: 6 8 7 2 7 6 2 6 | G147: 44 | H147: 45 | I147: false | J147: 1 | K147: 1618 | L147: 8 | M147: 1.8 | N147: 1 | O147: 9 | P147: =LOWER(TRIM(C147)) | Q147: =IF(I147="true",1,0) | R147: =IF(K147="","",K147) | S147: =IF(OR(H147="",H147<8,H147>72),"",J147) | T147: =IF(OR(P147="lyrics",P147="instrumental"),1,IF(AND(P147="none",COUNTIFS($B$2:$B$479,B147,$P$2:$P$479,"none")>=3),1,0))
A148: 51 | B148: Participant 4 | C148: instrumental | D148: 2026-10-11T17:11:12.295Z | E148: 1 | F148: 6 7 6 6 6 4 8 1 | G148: 44 | H148: 44 | I148: true | J148: 0 | K148: 3831 | L148: 8 | M148: 1.8 | N148: 1 | O148: 9 | P148: =LOWER(TRIM(C148)) | Q148: =IF(I148="true",1,0) | R148: =IF(K148="","",K148) | S148: =IF(OR(H148="",H148<8,H148>72),"",J148) | T148: =IF(OR(P148="lyrics",P148="instrumental"),1,IF(AND(P148="none",COUNTIFS($B$2:$B$479,B148,$P$2:$P$479,"none")>=3),1,0))
A149: 51 | B149: Participant 4 | C149: instrumental | D149: 2026-10-11T17:11:12.295Z | E149: 2 | F149: 4 1 8 5 8 8 1 8 | G149: 43 | H149: 48 | I149: false | J149: 5 | K149: 5758 | L149: 8 | M149: 1.8 | N149: 1 | O149: 9 | P149: =LOWER(TRIM(C149)) | Q149: =IF(I149="true",1,0) | R149: =IF(K149="","",K149) | S149: =IF(OR(H149="",H149<8,H149>72),"",J149) | T149: =IF(OR(P149="lyrics",P149="instrumental"),1,IF(AND(P149="none",COUNTIFS($B$2:$B$479,B149,$P$2:$P$479,"none")>=3),1,0))
A150: 51 | B150: Participant 4 | C150: instrumental | D150: 2026-10-11T17:11:12.295Z | E150: 3 | F150: 9 6 3 1 1 3 4 5 | G150: 32 | H150: 32 | I150: true | J150: 0 | K150: 1685 | L150: 8 | M150: 1.8 | N150: 1 | O150: 9 | P150: =LOWER(TRIM(C150)) | Q150: =IF(I150="true",1,0) | R150: =IF(K150="","",K150) | S150: =IF(OR(H150="",H150<8,H150>72),"",J150) | T150: =IF(OR(P150="lyrics",P150="instrumental"),1,IF(AND(P150="none",COUNTIFS($B$2:$B$479,B150,$P$2:$P$479,"none")>=3),1,0))
A151: 52 | B151: Participant 4 | C151: instrumental | D151: 2026-10-11T17:12:39.073Z | E151: 1 | F151: 1 5 5 6 4 4 6 8 | G151: 39 | H151: 39 | I151: true | J151: 0 | K151: 1882 | L151: 8 | M151: 1.8 | N151: 1 | O151: 9 | P151: =LOWER(TRIM(C151)) | Q151: =IF(I151="true",1,0) | R151: =IF(K151="","",K151) | S151: =IF(OR(H151="",H151<8,H151>72),"",J151) | T151: =IF(OR(P151="lyrics",P151="instrumental"),1,IF(AND(P151="none",COUNTIFS($B$2:$B$479,B151,$P$2:$P$479,"none")>=3),1,0))
A152: 52 | B152: Participant 4 | C152: instrumental | D152: 2026-10-11T17:12:39.073Z | E152: 2 | F152: 8 8 8 2 9 7 7 3 | G152: 52 | H152: 48 | I152: false | J152: 4 | K152: 7689 | L152: 8 | M152: 1.8 | N152: 1 | O152: 9 | P152: =LOWER(TRIM(C152)) | Q152: =IF(I152="true",1,0) | R152: =IF(K152="","",K152) | S152: =IF(OR(H152="",H152<8,H152>72),"",J152) | T152: =IF(OR(P152="lyrics",P152="instrumental"),1,IF(AND(P152="none",COUNTIFS($B$2:$B$479,B152,$P$2:$P$479,"none")>=3),1,0))
A153: 52 | B153: Participant 4 | C153: instrumental | D153: 2026-10-11T17:12:39.073Z | E153: 3 | F153: 9 8 1 4 2 3 5 2 | G153: 34 | H153: 34 | I153: true | J153: 0 | K153: 2934 | L153: 8 | M153: 1.8 | N153: 1 | O153: 9 | P153: =LOWER(TRIM(C153)) | Q153: =IF(I153="true",1,0) | R153: =IF(K153="","",K153) | S153: =IF(OR(H153="",H153<8,H153>72),"",J153) | T153: =IF(OR(P153="lyrics",P153="instrumental"),1,IF(AND(P153="none",COUNTIFS($B$2:$B$479,B153,$P$2:$P$479,"none")>=3),1,0))
A154: 53 | B154: Participant 4 | C154: lyrics | D154: 2026-10-11T17:13:48.422Z | E154: 1 | F154: 8 8 1 7 7 1 8 8 | G154: 48 | H154: 48 | I154: true | J154: 0 | K154: 1617 | L154: 8 | M154: 1.8 | N154: 1 | O154: 9 | P154: =LOWER(TRIM(C154)) | Q154: =IF(I154="true",1,0) | R154: =IF(K154="","",K154) | S154: =IF(OR(H154="",H154<8,H154>72),"",J154) | T154: =IF(OR(P154="lyrics",P154="instrumental"),1,IF(AND(P154="none",COUNTIFS($B$2:$B$479,B154,$P$2:$P$479,"none")>=3),1,0))
...

Sheet By person
A1: One row per person
A2: Formulas read All data. Practice silence is excluded. A silence block of three trials is kept.
A3: Person | B3: Lyrics trials | C3: Instrumental trials | D3: Silence trials | E3: Lyrics correct | F3: Instrumental correct | G3: Silence correct | H3: Accuracy difference | I3: Lyrics time (ms) | J3: Instrumental time (ms) | K3: Silence time (ms) | L3: Time difference (ms) | M3: Lyrics error | N3: Instrumental error | O3: Silence error | P3: Error difference | Q3: Lyrics − silence, accuracy | R3: Instrumental − silence, accuracy | S3: Lyrics − silence, time (ms) | T3: Instrumental − silence, time (ms) | U3: Accuracy difference, silence group | V3: Time difference, silence group | W3: Error difference, silence group
A4: anne | B4: =COUNTIFS(Names,A4,Cond,"lyrics",Scored,1) | C4: =COUNTIFS(Names,A4,Cond,"instrumental",Scored,1) | D4: =COUNTIFS(Names,A4,Cond,"none",Scored,1) | E4: =IF(B4=0,"",AVERAGEIFS(CorrectN,Names,A4,Cond,"lyrics",Scored,1)) | F4: =IF(C4=0,"",AVERAGEIFS(CorrectN,Names,A4,Cond,"instrumental",Scored,1)) | G4: =IF(D4=0,"",AVERAGEIFS(CorrectN,Names,A4,Cond,"none",Scored,1)) | H4: =IF(OR(E4="",F4=""),"",E4-F4) | I4: =IF(B4=0,"",AVERAGEIFS(RtN,Names,A4,Cond,"lyrics",Scored,1)) | J4: =IF(C4=0,"",AVERAGEIFS(RtN,Names,A4,Cond,"instrumental",Scored,1)) | K4: =IF(D4=0,"",AVERAGEIFS(RtN,Names,A4,Cond,"none",Scored,1)) | L4: =IF(OR(I4="",J4=""),"",I4-J4) | M4: =IF(B4=0,"",AVERAGEIFS(AbsN,Names,A4,Cond,"lyrics",Scored,1)) | N4: =IF(C4=0,"",AVERAGEIFS(AbsN,Names,A4,Cond,"instrumental",Scored,1)) | O4: =IF(D4=0,"",AVERAGEIFS(AbsN,Names,A4,Cond,"none",Scored,1)) | P4: =IF(OR(M4="",N4=""),"",M4-N4) | Q4: =IF(OR(E4="",G4=""),"",E4-G4) | R4: =IF(OR(F4="",G4=""),"",F4-G4) | S4: =IF(OR(I4="",K4=""),"",I4-K4) | T4: =IF(OR(J4="",K4=""),"",J4-K4) | U4: =IF(D4>=3,H4,"") | V4: =IF(D4>=3,L4,"") | W4: =IF(D4>=3,P4,"")
A5: aus | B5: =COUNTIFS(Names,A5,Cond,"lyrics",Scored,1) | C5: =COUNTIFS(Names,A5,Cond,"instrumental",Scored,1) | D5: =COUNTIFS(Names,A5,Cond,"none",Scored,1) | E5: =IF(B5=0,"",AVERAGEIFS(CorrectN,Names,A5,Cond,"lyrics",Scored,1)) | F5: =IF(C5=0,"",AVERAGEIFS(CorrectN,Names,A5,Cond,"instrumental",Scored,1)) | G5: =IF(D5=0,"",AVERAGEIFS(CorrectN,Names,A5,Cond,"none",Scored,1)) | H5: =IF(OR(E5="",F5=""),"",E5-F5) | I5: =IF(B5=0,"",AVERAGEIFS(RtN,Names,A5,Cond,"lyrics",Scored,1)) | J5: =IF(C5=0,"",AVERAGEIFS(RtN,Names,A5,Cond,"instrumental",Scored,1)) | K5: =IF(D5=0,"",AVERAGEIFS(RtN,Names,A5,Cond,"none",Scored,1)) | L5: =IF(OR(I5="",J5=""),"",I5-J5) | M5: =IF(B5=0,"",AVERAGEIFS(AbsN,Names,A5,Cond,"lyrics",Scored,1)) | N5: =IF(C5=0,"",AVERAGEIFS(AbsN,Names,A5,Cond,"instrumental",Scored,1)) | O5: =IF(D5=0,"",AVERAGEIFS(AbsN,Names,A5,Cond,"none",Scored,1)) | P5: =IF(OR(M5="",N5=""),"",M5-N5) | Q5: =IF(OR(E5="",G5=""),"",E5-G5) | R5: =IF(OR(F5="",G5=""),"",F5-G5) | S5: =IF(OR(I5="",K5=""),"",I5-K5) | T5: =IF(OR(J5="",K5=""),"",J5-K5) | U5: =IF(D5>=3,H5,"") | V5: =IF(D5>=3,L5,"") | W5: =IF(D5>=3,P5,"")
A6: benjamin | B6: =COUNTIFS(Names,A6,Cond,"lyrics",Scored,1) | C6: =COUNTIFS(Names,A6,Cond,"instrumental",Scored,1) | D6: =COUNTIFS(Names,A6,Cond,"none",Scored,1) | E6: =IF(B6=0,"",AVERAGEIFS(CorrectN,Names,A6,Cond,"lyrics",Scored,1)) | F6: =IF(C6=0,"",AVERAGEIFS(CorrectN,Names,A6,Cond,"instrumental",Scored,1)) | G6: =IF(D6=0,"",AVERAGEIFS(CorrectN,Names,A6,Cond,"none",Scored,1)) | H6: =IF(OR(E6="",F6=""),"",E6-F6) | I6: =IF(B6=0,"",AVERAGEIFS(RtN,Names,A6,Cond,"lyrics",Scored,1)) | J6: =IF(C6=0,"",AVERAGEIFS(RtN,Names,A6,Cond,"instrumental",Scored,1)) | K6: =IF(D6=0,"",AVERAGEIFS(RtN,Names,A6,Cond,"none",Scored,1)) | L6: =IF(OR(I6="",J6=""),"",I6-J6) | M6: =IF(B6=0,"",AVERAGEIFS(AbsN,Names,A6,Cond,"lyrics",Scored,1)) | N6: =IF(C6=0,"",AVERAGEIFS(AbsN,Names,A6,Cond,"instrumental",Scored,1)) | O6: =IF(D6=0,"",AVERAGEIFS(AbsN,Names,A6,Cond,"none",Scored,1)) | P6: =IF(OR(M6="",N6=""),"",M6-N6) | Q6: =IF(OR(E6="",G6=""),"",E6-G6) | R6: =IF(OR(F6="",G6=""),"",F6-G6) | S6: =IF(OR(I6="",K6=""),"",I6-K6) | T6: =IF(OR(J6="",K6=""),"",J6-K6) | U6: =IF(D6>=3,H6,"") | V6: =IF(D6>=3,L6,"") | W6: =IF(D6>=3,P6,"")
A7: Bommel | B7: =COUNTIFS(Names,A7,Cond,"lyrics",Scored,1) | C7: =COUNTIFS(Names,A7,Cond,"instrumental",Scored,1) | D7: =COUNTIFS(Names,A7,Cond,"none",Scored,1) | E7: =IF(B7=0,"",AVERAGEIFS(CorrectN,Names,A7,Cond,"lyrics",Scored,1)) | F7: =IF(C7=0,"",AVERAGEIFS(CorrectN,Names,A7,Cond,"instrumental",Scored,1)) | G7: =IF(D7=0,"",AVERAGEIFS(CorrectN,Names,A7,Cond,"none",Scored,1)) | H7: =IF(OR(E7="",F7=""),"",E7-F7) | I7: =IF(B7=0,"",AVERAGEIFS(RtN,Names,A7,Cond,"lyrics",Scored,1)) | J7: =IF(C7=0,"",AVERAGEIFS(RtN,Names,A7,Cond,"instrumental",Scored,1)) | K7: =IF(D7=0,"",AVERAGEIFS(RtN,Names,A7,Cond,"none",Scored,1)) | L7: =IF(OR(I7="",J7=""),"",I7-J7) | M7: =IF(B7=0,"",AVERAGEIFS(AbsN,Names,A7,Cond,"lyrics",Scored,1)) | N7: =IF(C7=0,"",AVERAGEIFS(AbsN,Names,A7,Cond,"instrumental",Scored,1)) | O7: =IF(D7=0,"",AVERAGEIFS(AbsN,Names,A7,Cond,"none",Scored,1)) | P7: =IF(OR(M7="",N7=""),"",M7-N7) | Q7: =IF(OR(E7="",G7=""),"",E7-G7) | R7: =IF(OR(F7="",G7=""),"",F7-G7) | S7: =IF(OR(I7="",K7=""),"",I7-K7) | T7: =IF(OR(J7="",K7=""),"",J7-K7) | U7: =IF(D7>=3,H7,"") | V7: =IF(D7>=3,L7,"") | W7: =IF(D7>=3,P7,"")
A8: Bram | B8: =COUNTIFS(Names,A8,Cond,"lyrics",Scored,1) | C8: =COUNTIFS(Names,A8,Cond,"instrumental",Scored,1) | D8: =COUNTIFS(Names,A8,Cond,"none",Scored,1) | E8: =IF(B8=0,"",AVERAGEIFS(CorrectN,Names,A8,Cond,"lyrics",Scored,1)) | F8: =IF(C8=0,"",AVERAGEIFS(CorrectN,Names,A8,Cond,"instrumental",Scored,1)) | G8: =IF(D8=0,"",AVERAGEIFS(CorrectN,Names,A8,Cond,"none",Scored,1)) | H8: =IF(OR(E8="",F8=""),"",E8-F8) | I8: =IF(B8=0,"",AVERAGEIFS(RtN,Names,A8,Cond,"lyrics",Scored,1)) | J8: =IF(C8=0,"",AVERAGEIFS(RtN,Names,A8,Cond,"instrumental",Scored,1)) | K8: =IF(D8=0,"",AVERAGEIFS(RtN,Names,A8,Cond,"none",Scored,1)) | L8: =IF(OR(I8="",J8=""),"",I8-J8) | M8: =IF(B8=0,"",AVERAGEIFS(AbsN,Names,A8,Cond,"lyrics",Scored,1)) | N8: =IF(C8=0,"",AVERAGEIFS(AbsN,Names,A8,Cond,"instrumental",Scored,1)) | O8: =IF(D8=0,"",AVERAGEIFS(AbsN,Names,A8,Cond,"none",Scored,1)) | P8: =IF(OR(M8="",N8=""),"",M8-N8) | Q8: =IF(OR(E8="",G8=""),"",E8-G8) | R8: =IF(OR(F8="",G8=""),"",F8-G8) | S8: =IF(OR(I8="",K8=""),"",I8-K8) | T8: =IF(OR(J8="",K8=""),"",J8-K8) | U8: =IF(D8>=3,H8,"") | V8: =IF(D8>=3,L8,"") | W8: =IF(D8>=3,P8,"")
A9: Cas | B9: =COUNTIFS(Names,A9,Cond,"lyrics",Scored,1) | C9: =COUNTIFS(Names,A9,Cond,"instrumental",Scored,1) | D9: =COUNTIFS(Names,A9,Cond,"none",Scored,1) | E9: =IF(B9=0,"",AVERAGEIFS(CorrectN,Names,A9,Cond,"lyrics",Scored,1)) | F9: =IF(C9=0,"",AVERAGEIFS(CorrectN,Names,A9,Cond,"instrumental",Scored,1)) | G9: =IF(D9=0,"",AVERAGEIFS(CorrectN,Names,A9,Cond,"none",Scored,1)) | H9: =IF(OR(E9="",F9=""),"",E9-F9) | I9: =IF(B9=0,"",AVERAGEIFS(RtN,Names,A9,Cond,"lyrics",Scored,1)) | J9: =IF(C9=0,"",AVERAGEIFS(RtN,Names,A9,Cond,"instrumental",Scored,1)) | K9: =IF(D9=0,"",AVERAGEIFS(RtN,Names,A9,Cond,"none",Scored,1)) | L9: =IF(OR(I9="",J9=""),"",I9-J9) | M9: =IF(B9=0,"",AVERAGEIFS(AbsN,Names,A9,Cond,"lyrics",Scored,1)) | N9: =IF(C9=0,"",AVERAGEIFS(AbsN,Names,A9,Cond,"instrumental",Scored,1)) | O9: =IF(D9=0,"",AVERAGEIFS(AbsN,Names,A9,Cond,"none",Scored,1)) | P9: =IF(OR(M9="",N9=""),"",M9-N9) | Q9: =IF(OR(E9="",G9=""),"",E9-G9) | R9: =IF(OR(F9="",G9=""),"",F9-G9) | S9: =IF(OR(I9="",K9=""),"",I9-K9) | T9: =IF(OR(J9="",K9=""),"",J9-K9) | U9: =IF(D9>=3,H9,"") | V9: =IF(D9>=3,L9,"") | W9: =IF(D9>=3,P9,"")
A10: Deelnemer 1 | B10: =COUNTIFS(Names,A10,Cond,"lyrics",Scored,1) | C10: =COUNTIFS(Names,A10,Cond,"instrumental",Scored,1) | D10: =COUNTIFS(Names,A10,Cond,"none",Scored,1) | E10: =IF(B10=0,"",AVERAGEIFS(CorrectN,Names,A10,Cond,"lyrics",Scored,1)) | F10: =IF(C10=0,"",AVERAGEIFS(CorrectN,Names,A10,Cond,"instrumental",Scored,1)) | G10: =IF(D10=0,"",AVERAGEIFS(CorrectN,Names,A10,Cond,"none",Scored,1)) | H10: =IF(OR(E10="",F10=""),"",E10-F10) | I10: =IF(B10=0,"",AVERAGEIFS(RtN,Names,A10,Cond,"lyrics",Scored,1)) | J10: =IF(C10=0,"",AVERAGEIFS(RtN,Names,A10,Cond,"instrumental",Scored,1)) | K10: =IF(D10=0,"",AVERAGEIFS(RtN,Names,A10,Cond,"none",Scored,1)) | L10: =IF(OR(I10="",J10=""),"",I10-J10) | M10: =IF(B10=0,"",AVERAGEIFS(AbsN,Names,A10,Cond,"lyrics",Scored,1)) | N10: =IF(C10=0,"",AVERAGEIFS(AbsN,Names,A10,Cond,"instrumental",Scored,1)) | O10: =IF(D10=0,"",AVERAGEIFS(AbsN,Names,A10,Cond,"none",Scored,1)) | P10: =IF(OR(M10="",N10=""),"",M10-N10) | Q10: =IF(OR(E10="",G10=""),"",E10-G10) | R10: =IF(OR(F10="",G10=""),"",F10-G10) | S10: =IF(OR(I10="",K10=""),"",I10-K10) | T10: =IF(OR(J10="",K10=""),"",J10-K10) | U10: =IF(D10>=3,H10,"") | V10: =IF(D10>=3,L10,"") | W10: =IF(D10>=3,P10,"")
A11: Deelnemer 2 | B11: =COUNTIFS(Names,A11,Cond,"lyrics",Scored,1) | C11: =COUNTIFS(Names,A11,Cond,"instrumental",Scored,1) | D11: =COUNTIFS(Names,A11,Cond,"none",Scored,1) | E11: =IF(B11=0,"",AVERAGEIFS(CorrectN,Names,A11,Cond,"lyrics",Scored,1)) | F11: =IF(C11=0,"",AVERAGEIFS(CorrectN,Names,A11,Cond,"instrumental",Scored,1)) | G11: =IF(D11=0,"",AVERAGEIFS(CorrectN,Names,A11,Cond,"none",Scored,1)) | H11: =IF(OR(E11="",F11=""),"",E11-F11) | I11: =IF(B11=0,"",AVERAGEIFS(RtN,Names,A11,Cond,"lyrics",Scored,1)) | J11: =IF(C11=0,"",AVERAGEIFS(RtN,Names,A11,Cond,"instrumental",Scored,1)) | K11: =IF(D11=0,"",AVERAGEIFS(RtN,Names,A11,Cond,"none",Scored,1)) | L11: =IF(OR(I11="",J11=""),"",I11-J11) | M11: =IF(B11=0,"",AVERAGEIFS(AbsN,Names,A11,Cond,"lyrics",Scored,1)) | N11: =IF(C11=0,"",AVERAGEIFS(AbsN,Names,A11,Cond,"instrumental",Scored,1)) | O11: =IF(D11=0,"",AVERAGEIFS(AbsN,Names,A11,Cond,"none",Scored,1)) | P11: =IF(OR(M11="",N11=""),"",M11-N11) | Q11: =IF(OR(E11="",G11=""),"",E11-G11) | R11: =IF(OR(F11="",G11=""),"",F11-G11) | S11: =IF(OR(I11="",K11=""),"",I11-K11) | T11: =IF(OR(J11="",K11=""),"",J11-K11) | U11: =IF(D11>=3,H11,"") | V11: =IF(D11>=3,L11,"") | W11: =IF(D11>=3,P11,"")
A12: Deelnemer 3 | B12: =COUNTIFS(Names,A12,Cond,"lyrics",Scored,1) | C12: =COUNTIFS(Names,A12,Cond,"instrumental",Scored,1) | D12: =COUNTIFS(Names,A12,Cond,"none",Scored,1) | E12: =IF(B12=0,"",AVERAGEIFS(CorrectN,Names,A12,Cond,"lyrics",Scored,1)) | F12: =IF(C12=0,"",AVERAGEIFS(CorrectN,Names,A12,Cond,"instrumental",Scored,1)) | G12: =IF(D12=0,"",AVERAGEIFS(CorrectN,Names,A12,Cond,"none",Scored,1)) | H12: =IF(OR(E12="",F12=""),"",E12-F12) | I12: =IF(B12=0,"",AVERAGEIFS(RtN,Names,A12,Cond,"lyrics",Scored,1)) | J12: =IF(C12=0,"",AVERAGEIFS(RtN,Names,A12,Cond,"instrumental",Scored,1)) | K12: =IF(D12=0,"",AVERAGEIFS(RtN,Names,A12,Cond,"none",Scored,1)) | L12: =IF(OR(I12="",J12=""),"",I12-J12) | M12: =IF(B12=0,"",AVERAGEIFS(AbsN,Names,A12,Cond,"lyrics",Scored,1)) | N12: =IF(C12=0,"",AVERAGEIFS(AbsN,Names,A12,Cond,"instrumental",Scored,1)) | O12: =IF(D12=0,"",AVERAGEIFS(AbsN,Names,A12,Cond,"none",Scored,1)) | P12: =IF(OR(M12="",N12=""),"",M12-N12) | Q12: =IF(OR(E12="",G12=""),"",E12-G12) | R12: =IF(OR(F12="",G12=""),"",F12-G12) | S12: =IF(OR(I12="",K12=""),"",I12-K12) | T12: =IF(OR(J12="",K12=""),"",J12-K12) | U12: =IF(D12>=3,H12,"") | V12: =IF(D12>=3,L12,"") | W12: =IF(D12>=3,P12,"")
A13: Deelnemer 4 | B13: =COUNTIFS(Names,A13,Cond,"lyrics",Scored,1) | C13: =COUNTIFS(Names,A13,Cond,"instrumental",Scored,1) | D13: =COUNTIFS(Names,A13,Cond,"none",Scored,1) | E13: =IF(B13=0,"",AVERAGEIFS(CorrectN,Names,A13,Cond,"lyrics",Scored,1)) | F13: =IF(C13=0,"",AVERAGEIFS(CorrectN,Names,A13,Cond,"instrumental",Scored,1)) | G13: =IF(D13=0,"",AVERAGEIFS(CorrectN,Names,A13,Cond,"none",Scored,1)) | H13: =IF(OR(E13="",F13=""),"",E13-F13) | I13: =IF(B13=0,"",AVERAGEIFS(RtN,Names,A13,Cond,"lyrics",Scored,1)) | J13: =IF(C13=0,"",AVERAGEIFS(RtN,Names,A13,Cond,"instrumental",Scored,1)) | K13: =IF(D13=0,"",AVERAGEIFS(RtN,Names,A13,Cond,"none",Scored,1)) | L13: =IF(OR(I13="",J13=""),"",I13-J13) | M13: =IF(B13=0,"",AVERAGEIFS(AbsN,Names,A13,Cond,"lyrics",Scored,1)) | N13: =IF(C13=0,"",AVERAGEIFS(AbsN,Names,A13,Cond,"instrumental",Scored,1)) | O13: =IF(D13=0,"",AVERAGEIFS(AbsN,Names,A13,Cond,"none",Scored,1)) | P13: =IF(OR(M13="",N13=""),"",M13-N13) | Q13: =IF(OR(E13="",G13=""),"",E13-G13) | R13: =IF(OR(F13="",G13=""),"",F13-G13) | S13: =IF(OR(I13="",K13=""),"",I13-K13) | T13: =IF(OR(J13="",K13=""),"",J13-K13) | U13: =IF(D13>=3,H13,"") | V13: =IF(D13>=3,L13,"") | W13: =IF(D13>=3,P13,"")
A14: Deelnemer 5 | B14: =COUNTIFS(Names,A14,Cond,"lyrics",Scored,1) | C14: =COUNTIFS(Names,A14,Cond,"instrumental",Scored,1) | D14: =COUNTIFS(Names,A14,Cond,"none",Scored,1) | E14: =IF(B14=0,"",AVERAGEIFS(CorrectN,Names,A14,Cond,"lyrics",Scored,1)) | F14: =IF(C14=0,"",AVERAGEIFS(CorrectN,Names,A14,Cond,"instrumental",Scored,1)) | G14: =IF(D14=0,"",AVERAGEIFS(CorrectN,Names,A14,Cond,"none",Scored,1)) | H14: =IF(OR(E14="",F14=""),"",E14-F14) | I14: =IF(B14=0,"",AVERAGEIFS(RtN,Names,A14,Cond,"lyrics",Scored,1)) | J14: =IF(C14=0,"",AVERAGEIFS(RtN,Names,A14,Cond,"instrumental",Scored,1)) | K14: =IF(D14=0,"",AVERAGEIFS(RtN,Names,A14,Cond,"none",Scored,1)) | L14: =IF(OR(I14="",J14=""),"",I14-J14) | M14: =IF(B14=0,"",AVERAGEIFS(AbsN,Names,A14,Cond,"lyrics",Scored,1)) | N14: =IF(C14=0,"",AVERAGEIFS(AbsN,Names,A14,Cond,"instrumental",Scored,1)) | O14: =IF(D14=0,"",AVERAGEIFS(AbsN,Names,A14,Cond,"none",Scored,1)) | P14: =IF(OR(M14="",N14=""),"",M14-N14) | Q14: =IF(OR(E14="",G14=""),"",E14-G14) | R14: =IF(OR(F14="",G14=""),"",F14-G14) | S14: =IF(OR(I14="",K14=""),"",I14-K14) | T14: =IF(OR(J14="",K14=""),"",J14-K14) | U14: =IF(D14>=3,H14,"") | V14: =IF(D14>=3,L14,"") | W14: =IF(D14>=3,P14,"")
A15: Deelnemer 6 | B15: =COUNTIFS(Names,A15,Cond,"lyrics",Scored,1) | C15: =COUNTIFS(Names,A15,Cond,"instrumental",Scored,1) | D15: =COUNTIFS(Names,A15,Cond,"none",Scored,1) | E15: =IF(B15=0,"",AVERAGEIFS(CorrectN,Names,A15,Cond,"lyrics",Scored,1)) | F15: =IF(C15=0,"",AVERAGEIFS(CorrectN,Names,A15,Cond,"instrumental",Scored,1)) | G15: =IF(D15=0,"",AVERAGEIFS(CorrectN,Names,A15,Cond,"none",Scored,1)) | H15: =IF(OR(E15="",F15=""),"",E15-F15) | I15: =IF(B15=0,"",AVERAGEIFS(RtN,Names,A15,Cond,"lyrics",Scored,1)) | J15: =IF(C15=0,"",AVERAGEIFS(RtN,Names,A15,Cond,"instrumental",Scored,1)) | K15: =IF(D15=0,"",AVERAGEIFS(RtN,Names,A15,Cond,"none",Scored,1)) | L15: =IF(OR(I15="",J15=""),"",I15-J15) | M15: =IF(B15=0,"",AVERAGEIFS(AbsN,Names,A15,Cond,"lyrics",Scored,1)) | N15: =IF(C15=0,"",AVERAGEIFS(AbsN,Names,A15,Cond,"instrumental",Scored,1)) | O15: =IF(D15=0,"",AVERAGEIFS(AbsN,Names,A15,Cond,"none",Scored,1)) | P15: =IF(OR(M15="",N15=""),"",M15-N15) | Q15: =IF(OR(E15="",G15=""),"",E15-G15) | R15: =IF(OR(F15="",G15=""),"",F15-G15) | S15: =IF(OR(I15="",K15=""),"",I15-K15) | T15: =IF(OR(J15="",K15=""),"",J15-K15) | U15: =IF(D15>=3,H15,"") | V15: =IF(D15>=3,L15,"") | W15: =IF(D15>=3,P15,"")
... A32: wouter | B32: =COUNTIFS(Names,A32,Cond,"lyrics",Scored,1) | C32: =COUNTIFS(Names,A32,Cond,"instrumental",Scored,1) | D32: =COUNTIFS(Names,A32,Cond,"none",Scored,1) | E32: =IF(B32=0,"",AVERAGEIFS(CorrectN,Names,A32,Cond,"lyrics",Scored,1)) | F32: =IF(C32=0,"",AVERAGEIFS(CorrectN,Names,A32,Cond,"instrumental",Scored,1)) | G32: =IF(D32=0,"",AVERAGEIFS(CorrectN,Names,A32,Cond,"none",Scored,1)) | H32: =IF(OR(E32="",F32=""),"",E32-F32) | I32: =IF(B32=0,"",AVERAGEIFS(RtN,Names,A32,Cond,"lyrics",Scored,1)) | J32: =IF(C32=0,"",AVERAGEIFS(RtN,Names,A32,Cond,"instrumental",Scored,1)) | K32: =IF(D32=0,"",AVERAGEIFS(RtN,Names,A32,Cond,"none",Scored,1)) | L32: =IF(OR(I32="",J32=""),"",I32-J32) | M32: =IF(B32=0,"",AVERAGEIFS(AbsN,Names,A32,Cond,"lyrics",Scored,1)) | N32: =IF(C32=0,"",AVERAGEIFS(AbsN,Names,A32,Cond,"instrumental",Scored,1)) | O32: =IF(D32=0,"",AVERAGEIFS(AbsN,Names,A32,Cond,"none",Scored,1)) | P32: =IF(OR(M32="",N32=""),"",M32-N32) | Q32: =IF(OR(E32="",G32=""),"",E32-G32) | R32: =IF(OR(F32="",G32=""),"",F32-G32) | S32: =IF(OR(I32="",K32=""),"",I32-K32) | T32: =IF(OR(J32="",K32=""),"",J32-K32) | U32: =IF(D32>=3,H32,"") | V32: =IF(D32>=3,L32,"") | W32: =IF(D32>=3,P32,"")

Sheet Results
A1: Lyrics versus instrumental music
A2: Within-person paired t-tests. Every figure on this sheet is a formula.
A4: Sample
A5: People | B5: Lyrics trials | C5: Instrumental trials | D5: Scored silence trials
A6: =COUNTA('By person'!A4:A32) | B6: =SUM('By person'!B4:B32) | C6: =SUM('By person'!C4:C32) | D6: =SUM('By person'!D4:D32)
A8: Planned comparison: lyrics minus instrumental
B9: Accuracy | C9: Response time (ms) | D9: Absolute error (points)
A10: Mean, lyrics | B10: =AVERAGE('By person'!E4:E32) | C10: =AVERAGE('By person'!I4:I32) | D10: =AVERAGE('By person'!M4:M32)
A11: Mean, instrumental | B11: =AVERAGE('By person'!F4:F32) | C11: =AVERAGE('By person'!J4:J32) | D11: =AVERAGE('By person'!N4:N32)
A12: Difference (lyrics − instrumental) | B12: =AVERAGE('By person'!H4:H32) | C12: =AVERAGE('By person'!L4:L32) | D12: =AVERAGE('By person'!P4:P32)
A13: SD of the differences | B13: =STDEV.S('By person'!H4:H32) | C13: =STDEV.S('By person'!L4:L32) | D13: =STDEV.S('By person'!P4:P32)
A14: People (n) | B14: =COUNT('By person'!H4:H32) | C14: =COUNT('By person'!L4:L32) | D14: =COUNT('By person'!P4:P32)
A15: t | B15: =B12/(B13/SQRT(B14)) | C15: =C12/(C13/SQRT(C14)) | D15: =D12/(D13/SQRT(D14))
A16: df | B16: =B14-1 | C16: =C14-1 | D16: =D14-1
A17: Two-sided p | B17: =T.DIST.2T(ABS(B15),B16) | C17: =T.DIST.2T(ABS(C15),C16) | D17: =T.DIST.2T(ABS(D15),D16)
A18: One-sided p, lyrics lower | B18: =T.DIST(B15,B16,TRUE) | C18: — | D18: —
A19: 95% CI, low | B19: =B12-T.INV.2T(0.05,B16)*(B13/SQRT(B14)) | C19: =C12-T.INV.2T(0.05,C16)*(C13/SQRT(C14)) | D19: =D12-T.INV.2T(0.05,D16)*(D13/SQRT(D14))
A20: 95% CI, high | B20: =B12+T.INV.2T(0.05,B16)*(B13/SQRT(B14)) | C20: =C12+T.INV.2T(0.05,C16)*(C13/SQRT(C14)) | D20: =D12+T.INV.2T(0.05,D16)*(D13/SQRT(D14))
A21: Cohen's dz | B21: =B12/B13 | C21: =C12/C13 | D21: =D12/D13
A22: Negative differences | B22: =COUNTIF('By person'!H4:H32,"<0") | C22: =COUNTIF('By person'!L4:L32,"<0") | D22: =COUNTIF('By person'!P4:P32,"<0")
A23: Positive differences | B23: =COUNTIF('By person'!H4:H32,">0") | C23: =COUNTIF('By person'!L4:L32,">0") | D23: =COUNTIF('By person'!P4:P32,">0")
A24: Ties | B24: =COUNTIF('By person'!H4:H32,0) | C24: =COUNTIF('By person'!L4:L32,0) | D24: =COUNTIF('By person'!P4:P32,0)
A26: Silence block
A27: Eight people with three silence trials: Bommel, Bram, Cas, Fay, Floor, Gerdien, Lotte, Lotte Jr. Joseline's sessions have no silence rows.
A28: Contrast | B28: Mean difference | C28: t | D28: df | E28: Two-sided p | F28: 95% CI low | G28: 95% CI high | H28: Cohen's dz
A29: Accuracy, lyrics − instrumental | B29: =AVERAGE('By person'!U4:U32) | C29: =B29/(STDEV.S('By person'!U4:U32)/SQRT(I29)) | D29: =I29-1 | E29: =T.DIST.2T(ABS(C29),D29) | F29: =B29-T.INV.2T(0.05,D29)*(STDEV.S('By person'!U4:U32)/SQRT(I29)) | G29: =B29+T.INV.2T(0.05,D29)*(STDEV.S('By person'!U4:U32)/SQRT(I29)) | H29: =B29/STDEV.S('By person'!U4:U32) | I29: =COUNT('By person'!U4:U32)
A30: Accuracy, lyrics − silence | B30: =AVERAGE('By person'!Q4:Q32) | C30: =B30/(STDEV.S('By person'!Q4:Q32)/SQRT(I30)) | D30: =I30-1 | E30: =T.DIST.2T(ABS(C30),D30) | F30: =B30-T.INV.2T(0.05,D30)*(STDEV.S('By person'!Q4:Q32)/SQRT(I30)) | G30: =B30+T.INV.2T(0.05,D30)*(STDEV.S('By person'!Q4:Q32)/SQRT(I30)) | H30: =B30/STDEV.S('By person'!Q4:Q32) | I30: =COUNT('By person'!Q4:Q32)
A31: Accuracy, instrumental − silence | B31: =AVERAGE('By person'!R4:R32) | C31: =B31/(STDEV.S('By person'!R4:R32)/SQRT(I31)) | D31: =I31-1 | E31: =T.DIST.2T(ABS(C31),D31) | F31: =B31-T.INV.2T(0.05,D31)*(STDEV.S('By person'!R4:R32)/SQRT(I31)) | G31: =B31+T.INV.2T(0.05,D31)*(STDEV.S('By person'!R4:R32)/SQRT(I31)) | H31: =B31/STDEV.S('By person'!R4:R32) | I31: =COUNT('By person'!R4:R32)
A32: Time (ms), lyrics − instrumental | B32: =AVERAGE('By person'!V4:V32) | C32: =B32/(STDEV.S('By person'!V4:V32)/SQRT(I32)) | D32: =I32-1 | E32: =T.DIST.2T(ABS(C32),D32) | F32: =B32-T.INV.2T(0.05,D32)*(STDEV.S('By person'!V4:V32)/SQRT(I32)) | G32: =B32+T.INV.2T(0.05,D32)*(STDEV.S('By person'!V4:V32)/SQRT(I32)) | H32: =B32/STDEV.S('By person'!V4:V32) | I32: =COUNT('By person'!V4:V32)
A33: Time (ms), lyrics − silence | B33: =AVERAGE('By person'!S4:S32) | C33: =B33/(STDEV.S('By person'!S4:S32)/SQRT(I33)) | D33: =I33-1 | E33: =T.DIST.2T(ABS(C33),D33) | F33: =B33-T.INV.2T(0.05,D33)*(STDEV.S('By person'!S4:S32)/SQRT(I33)) | G33: =B33+T.INV.2T(0.05,D33)*(STDEV.S('By person'!S4:S32)/SQRT(I33)) | H33: =B33/STDEV.S('By person'!S4:S32) | I33: =COUNT('By person'!S4:S32)
A34: Time (ms), instrumental − silence | B34: =AVERAGE('By person'!T4:T32) | C34: =B34/(STDEV.S('By person'!T4:T32)/SQRT(I34)) | D34: =I34-1 | E34: =T.DIST.2T(ABS(C34),D34) | F34: =B34-T.INV.2T(0.05,D34)*(STDEV.S('By person'!T4:T32)/SQRT(I34)) | G34: =B34+T.INV.2T(0.05,D34)*(STDEV.S('By person'!T4:T32)/SQRT(I34)) | H34: =B34/STDEV.S('By person'!T4:T32) | I34: =COUNT('By person'!T4:T32)
A36: How to read this
A37: Source is data/combined.csv. One row there is one trial. The person is the name.
A38: Each person contributes one number per condition: the mean of that person's scored trials. Someone with 3 trials and someone with 9 trials each count once.
A39: A negative accuracy difference means fewer correct sums with lyrics. A positive time difference means slower with lyrics. A positive error difference means farther from the right total.
A40: Practice silence, the opening pair of none trials, stays out. Silence stays in only when a person has at least three silence trials.
A41: The stored label Lyrics is treated as lyrics. Blank answers count as wrong. Absolute error uses only answers from 8 through 72; other answers still count as wrong for accuracy.
A42: The t-test is one-sample on the within-person differences, against 0. df = n − 1. The interval uses T.INV.2T. Cohen's dz is the mean difference divided by the SD of the differences.
A43: The one-sided p-value is the lower tail, for the hypothesis that accuracy is lower with lyrics. Response time and absolute error are reported two-sided.
A44: aus has 6 instrumental trials. Participant 3 has 12. Five people saw each digit for 1.5 seconds: anne, aus, wouter, Participant 6, Participant 7. Those trials stay in.
...

Sheet Accuracy
A1: Accuracy
A2: Proportion correct. The bars are formulas from the By person sheet.
A4: Condition | B4: Mean proportion correct
A5: Lyrics | B5: =AVERAGE('By person'!E4:E32)
A6: Instrumental | B6: =AVERAGE('By person'!F4:F32)
A17: Sorted from a lower lyrics score toward a higher one. The top of the chart is the largest drop with lyrics. Values update if the trials change; this order is the order at the time the file was built.
A19: Person | B19: Lyrics − instrumental
A20: Participant 5 | B20: =INDEX('By person'!$H$4:$H$32,MATCH(A20,'By person'!$A$4:$A$32,0))
A21: Fay | B21: =INDEX('By person'!$H$4:$H$32,MATCH(A21,'By person'!$A$4:$A$32,0))
A22: Floor | B22: =INDEX('By person'!$H$4:$H$32,MATCH(A22,'By person'!$A$4:$A$32,0))
A23: Participant 6 | B23: =INDEX('By person'!$H$4:$H$32,MATCH(A23,'By person'!$A$4:$A$32,0))
A24: wouter | B24: =INDEX('By person'!$H$4:$H$32,MATCH(A24,'By person'!$A$4:$A$32,0))
A25: Deelnemer 4 | B25: =INDEX('By person'!$H$4:$H$32,MATCH(A25,'By person'!$A$4:$A$32,0))
A26: Mila | B26: =INDEX('By person'!$H$4:$H$32,MATCH(A26,'By person'!$A$4:$A$32,0))
A27: anne | B27: =INDEX('By person'!$H$4:$H$32,MATCH(A27,'By person'!$A$4:$A$32,0))
A28: benjamin | B28: =INDEX('By person'!$H$4:$H$32,MATCH(A28,'By person'!$A$4:$A$32,0))
A29: Deelnemer 6 | B29: =INDEX('By person'!$H$4:$H$32,MATCH(A29,'By person'!$A$4:$A$32,0))
A30: Milo | B30: =INDEX('By person'!$H$4:$H$32,MATCH(A30,'By person'!$A$4:$A$32,0))
A31: Participant 4 | B31: =INDEX('By person'!$H$4:$H$32,MATCH(A31,'By person'!$A$4:$A$32,0))
... A48: Deelnemer 1 | B48: =INDEX('By person'!$H$4:$H$32,MATCH(A48,'By person'!$A$4:$A$32,0))

Sheet Response time
A1: Response time
A2: Mean milliseconds from the moment the answer box appeared. Higher is slower.
A4: Condition | B4: Mean response time (ms)
A5: Lyrics | B5: =AVERAGE('By person'!I4:I32)
A6: Instrumental | B6: =AVERAGE('By person'!J4:J32)
A17: Sorted from faster with lyrics toward slower with lyrics. The top of the chart is the largest slowdown. Positive means the person took longer with lyrics.
A19: Person | B19: Lyrics − instrumental (ms)
A20: Participant 2 | B20: =INDEX('By person'!$L$4:$L$32,MATCH(A20,'By person'!$A$4:$A$32,0))
A21: Participant 4 | B21: =INDEX('By person'!$L$4:$L$32,MATCH(A21,'By person'!$A$4:$A$32,0))
A22: Participant 3 | B22: =INDEX('By person'!$L$4:$L$32,MATCH(A22,'By person'!$A$4:$A$32,0))
A23: joran | B23: =INDEX('By person'!$L$4:$L$32,MATCH(A23,'By person'!$A$4:$A$32,0))
A24: benjamin | B24: =INDEX('By person'!$L$4:$L$32,MATCH(A24,'By person'!$A$4:$A$32,0))
A25: Deelnemer 5 | B25: =INDEX('By person'!$L$4:$L$32,MATCH(A25,'By person'!$A$4:$A$32,0))
A26: Deelnemer 1 | B26: =INDEX('By person'!$L$4:$L$32,MATCH(A26,'By person'!$A$4:$A$32,0))
A27: Participant 6 | B27: =INDEX('By person'!$L$4:$L$32,MATCH(A27,'By person'!$A$4:$A$32,0))
A28: aus | B28: =INDEX('By person'!$L$4:$L$32,MATCH(A28,'By person'!$A$4:$A$32,0))
A29: Participant 1 | B29: =INDEX('By person'!$L$4:$L$32,MATCH(A29,'By person'!$A$4:$A$32,0))
A30: Participant 7 | B30: =INDEX('By person'!$L$4:$L$32,MATCH(A30,'By person'!$A$4:$A$32,0))
A31: Gerdien | B31: =INDEX('By person'!$L$4:$L$32,MATCH(A31,'By person'!$A$4:$A$32,0))
... A48: anne | B48: =INDEX('By person'!$L$4:$L$32,MATCH(A48,'By person'!$A$4:$A$32,0))

Sheet Silence
A1: Silence, instrumental, and lyrics
A2: The eight people who completed a silence block of three trials. Means are formulas.
A4: Condition | B4: Proportion correct | C4: Mean time (ms)
A5: Silence | B5: =AVERAGEIF('By person'!$D$4:$D$32,">=3",'By person'!G4:G32) | C5: =AVERAGEIF('By person'!$D$4:$D$32,">=3",'By person'!K4:K32)
A6: Instrumental | B6: =AVERAGEIF('By person'!$D$4:$D$32,">=3",'By person'!F4:F32) | C6: =AVERAGEIF('By person'!$D$4:$D$32,">=3",'By person'!J4:J32)
A7: Lyrics | B7: =AVERAGEIF('By person'!$D$4:$D$32,">=3",'By person'!E4:E32) | C7: =AVERAGEIF('By person'!$D$4:$D$32,">=3",'By person'!I4:I32)
A9: Silence was the most accurate and the fastest in this group of eight. Lyrics were the least accurate and the slowest. The tests for these contrasts are on the Results sheet.
